<?xml version="1.0"?>
<!-- Simple Humanoid URDF Example -->
<robot name="simple_humanoid">
  <!-- Base Link -->
  <link name="base_link">
    <visual>
      <geometry>
        <box size="0.3 0.2 0.1" />
      </geometry>
      <material name="white">
        <color rgba="1 1 1 1" />
      </material>
    </visual>
    <collision>
      <geometry>
        <box size="0.3 0.2 0.1" />
      </geometry>
    </collision>
    <inertial>
      <mass value="5.0" />
      <origin xyz="0 0 0" />
      <inertia ixx="0.1" ixy="0" ixz="0" iyy="0.1" iyz="0" izz="0.1" />
    </inertial>
  </link>

  <!-- Torso -->
  <link name="torso">
    <visual>
      <geometry>
        <box size="0.2 0.1 0.4" />
      </geometry>
      <material name="blue">
        <color rgba="0 0 1 1" />
      </material>
    </visual>
    <collision>
      <geometry>
        <box size="0.2 0.1 0.4" />
      </geometry>
    </collision>
    <inertial>
      <mass value="3.0" />
      <origin xyz="0 0 0" />
      <inertia ixx="0.05" ixy="0" ixz="0" iyy="0.05" iyz="0" izz="0.05" />
    </inertial>
  </link>

  <joint name="base_to_torso" type="fixed">
    <parent link="base_link" />
    <child link="torso" />
    <origin xyz="0 0 0.25" />
  </joint>

  <!-- Head -->
  <link name="head">
    <visual>
      <geometry>
        <sphere radius="0.1" />
      </geometry>
      <material name="skin">
        <color rgba="1 0.8 0.6 1" />
      </material>
    </visual>
    <collision>
      <geometry>
        <sphere radius="0.1" />
      </geometry>
    </collision>
    <inertial>
      <mass value="1.0" />
      <origin xyz="0 0 0" />
      <inertia ixx="0.002" ixy="0" ixz="0" iyy="0.002" iyz="0" izz="0.002" />
    </inertial>
  </link>

  <joint name="torso_to_head" type="revolute">
    <parent link="torso" />
    <child link="head" />
    <origin xyz="0 0 0.25" />
    <axis xyz="0 1 0" />
    <limit lower="-0.5" upper="0.5" effort="10" velocity="2" />
  </joint>
</robot>